Workbook

Sheet Descripciones
A1: CODIGO 2017 ALFANÚMERICO | B1: NOMBRE | C1: CODIGO 2017 ALFANÚMERICO | D1: CÓDIGO DE ÁREA 2017 | E1: AREA GENERAL | F1: SUBAREA | G1: ÁREA ESPECIFICA | H1: CÓDIGO NIVEL 2017 | I1: NIVEL ACTUAL( 2017) | J1: DESCRIPCION | K1: REPORTA A | L1: ESTUDIOS REQUERIDOS | M1: EXPERIENCIA REQUERIDA | N1: SEGUNDO IDIOMA
A2: CPAD00 | B2: PRESIDENTE - REGIONAL | C2: CPAD00 | D2: 4 | E2: CORPORATIVO | F2: ALTA DIRECCION | G2: REGIONAL | H2: 0 | I2: 1ER DIRECTIVO | J2: Planificar, organizar, dirigir y controlar todas las actividades de la compañía en una zona geográfica determinada cubriendo siempre más de un país. Identificar y recomendar la estrategia a corto, mediano y largo plazo, identificando y desarrollando nuevas oportunidades de negocio. Reporta generalmente a la Casa Matriz | K2: Casa matriz / Junta directiva | L2: Especialización | M2: Diversificada (15 años) | N2: Dominarlo
A3: CPAD03 | B3: GERENTE GENERAL | C3: CPAD03 | D3: 4 | E3: CORPORATIVO | F3: ALTA DIRECCION | G3: PAIS | H3: 0 | I3: 1ER DIRECTIVO | J3: Dirigir y hacer cumplir los planes generales de la empresa a través de los gerentes de cada área, para garantizar el aprovechamiento de los recursos humanos, financieros, materiales y tecnológicos en busca de los objetivos finales de la organización. | K3: Presidente / Junta directiva | L3: Especialización | M3: Más de 10 años | N3: Dominarlo
A4: CPAD01 | B4: PRESIDENTE PAIS | C4: CPAD01 | D4: 4 | E4: CORPORATIVO | F4: ALTA DIRECCION | G4: PAIS | H4: 0 | I4: 1ER DIRECTIVO | J4: Responsable de la dirección de una empresa a nivel nacional o local, con base en las orientaciones de una Junta Directiva o Casa Matriz. Es responsable de cumplir con la misión de la empresa y lograr sus objetivos fundamentales, mediante la definición y puesta en práctica de estratégias y políticas en todos sus ámbitos y la dirección de todas las áreas de la organización (comercial, operaciones, financiera, gestión humana, administración).El cargo requiere de un profesional con postgrado en un área afín a su cargo y amplia experiencia de negocios. Por lo general reporta a Casa Matriz. | K4: Junta directiva | L4: Especialización | M4: Diversificada (15 años) | N4: Dominarlo
A5: CPAD02 | B5: PRESIDENTE/ GERENTE GENERAL - PAIS | C5: CPAD02 | D5: 4 | E5: CORPORATIVO | F5: ALTA DIRECCION | G5: PAIS | H5: 0 | I5: 1ER DIRECTIVO | J5: Dirigir, planear y garantizar el cumplimiento de los resultados operacionales, comerciales y financieros de la compañía identificar y recomendar la estrategia a corto, mediano y largo plazo, identificando y desarrollando nuevas oportunidades de negocio. Máxima autoridad de la organización. | K5: Presidente / Junta directiva | L5: Especialización | M5: Diversificada (15 años) | N5: Dominarlo
A6: COVS10 | B6: VICEPRESIDENTE COMERCIAL | C6: COVS10 | D6: 3 | E6: COMERCIAL | F6: VENTAS | G6: VENTAS | H6: 1 | I6: EJECUTIVOS SR | J6: Formular y fijar las políticas comerciales de la entidad, dirigidas a las diferentes regionales, sucursales y agencias que existen en todo el país. Planear, dirigir y controlar la promoción y difusión de los diferentes productos y la adecuada prestación de los servicios existentes. | K6: Presidente / Gerente general | L6: Especialización | M6: Varias Especialidades (10 años) | N6: Dominarlo
A7: SGSN10 | B7: VICEPRESIDENTE SINIESTROS | C7: SGSN10 | D7: 22 | E7: SERVICIOS FINANCIEROS Y SEGUROS | F7: SINIESTROS | G7: SINIESTROS | H7: 1 | I7: EJECUTIVOS SR | J7: Define los parámetros operativos, estableciendo prioridades de recuperación de siniestros de terceros, reaseguros y coseguros. Mantiene contacto con otras compañías, buscando agilizar los procesos de resarcimiento para la empresa. Define también la posición de su compañía como líder o coaseguradora dentro de las propuestas de negocio. Acompaña la evolución de los procesos de resarcimiento / recuperación de los siniestros causados por terceros. Controla índices generales de siniestralidad de la Cia., priorizando la agilización de la atención de los pedidos de indemnización. | K7: Presidente | L7: Especialización | M7: Varias Especialidades (10 años) | N7: Dominarlo
A8: EDRT10 | B8: RECTOR | C8: EDRT10 | D8: 20 | E8: SERVICIOS EDUCATIVOS | F8: RECTORIA | G8: SERVICIOS EDUCATIVOS | H8: 1 | I8: EJECUTIVOS SR | J8: Planea, dirigir y soportar la gestión de docencia, investigación, proyección social y bienestar universitario, mediante una organización administrativa eficiente en el manejo de los recursos humanos, físicos, técnicos y financieros, que provea a los alumnos y profesores las mejores condiciones para su desarrollo académico. | K8: Junta directiva | L8: Especialización | M8: Más de 10 años | N8: Dominarlo
A9: COSC12 | B9: VICEPRESIDENTE SERVICIOS AL CLIENTE | C9: COSC12 | D9: 3 | E9: COMERCIAL | F9: SERVICIO AL CLIENTE | G9: SERVICIO AL CLIENTE | H9: 1 | I9: EJECUTIVOS SR | J9: Dirige la función de Servicio al Cliente. Responsable por establecer políticas y procedimientos para proveer soporte técnico y no técnico a los clientes de acuerdo con las obligaciones contractuales. Puede ser responsable por desarrollar y vigilar la implementacion de estrategias de fidelizacion y satisfaccion. | K9: Presidente | L9: Especialización | M9: Varias Especialidades (10 años) | N9: Dominarlo
A10: FISR10 | B10: VICEPRESIDENTE GERENCIAMENTO RIESGO | C10: FISR10 | D10: 5 | E10: FINANCIERA | F10: SEGUROS / RIESGO FINANCIERO | G10: RIESGO | H10: 1 | I10: EJECUTIVOS SR | J10: Responsable de implementar y dirigir la evaluación y administración de todos los riesgos a los que pueden estar expuestos las instalaciones, inventarios y otras propiedades de la compañía, tales como inspecciones de riesgos, los estados financieros y de planeacion. | K10: Presidente | L10: Especialización | M10: Varias Especialidades (10 años) | N10: Dominarlo
A11: MAPR10 | B11: VICEPRESIDENTE MANUFACTURA | C11: MAPR10 | D11: 11 | E11: MANUFACTURA E INDUSTRIA | F11: PRODUCCION | G11: PRODUCCION | H11: 1 | I11: EJECUTIVOS SR | J11: Responder por todas las operaciones de fabricación, mantenimiento y proyectos en una empresa o grupo de empresas. Informar al presidente de la compañía; tiene a su cargo los gerentes o superintendentes de las diversas plantas o áreas. | K11: Presidente | L11: Especialización | M11: Varias Especialidades (10 años) | N11: Dominarlo
A12: MAGN10 | B12: VICEPRESIDENTE MANUFACTURA | C12: MAGN10 | D12: 11 | E12: MANUFACTURA E INDUSTRIA | F12: PRODUCCION | G12: PRODUCCION | H12: 1 | I12: EJECUTIVOS SR | J12: Otros Nombres: Vicepresidente de Manufactura, Vicepresidente de Producción, Vicepresidente de Operaciones de Planta. Responsable de las estrategias de manufactura de la empresa en el ámbito nacional o local, con base en las orientaciones de la Presidencia/Gerente General. Dirige los procesos productivos de los distintos centros o plantas de producción. Evalúa las oportunidades de desarrollo tecnológico y lleva a cabo proyectos de mejoramiento y expansión. Se requiere un profesional con postgrado en un área afín a su cargo y amplia experiencia en su campo. Reporta a: Presidente. | K12: Presidente | L12: Especialización | M12: Varias Especialidades (10 años) | N12: Dominarlo
A13: CPAD10 | B13: VICEPRESIDENTE EJECUTIVO | C13: CPAD10 | D13: 4 | E13: CORPORATIVO | F13: ALTA DIRECCION | G13: PAIS | H13: 1 | I13: EJECUTIVOS SR | J13: Coordinar la ejecución de estrategias y políticas generales, dirigidas a obtener el mejor aprovechamiento de los recursos, el desarrollo de la institución y responder por la gestión de todas las áreas a su cargo, de tal forma que se logren los objetivos finales de la organización. En ausencia del Presidente, asume las funciones y representa a la entidad tanto interna como externamente. | K13: Presidente | L13: Especialización | M13: Varias Especialidades (10 años) | N13: Dominarlo
... A33: ATVT10 | B33: VICEPRESIDENTE VENTAS ALTA TECNOLOGÍA (GENÉRICO) | C33: ATVT10 | D33: 16 | E33: ALTA TECNOLOGÍA Y TELECOMUNICACIONES | F33: VENTAS | G33: Alta Tecnología | H33: 1 | I33: EJECUTIVOS SR | J33: Responsable por el logro de los objetivos de ventas de una región ó zona muy significativa. Desarrolla e implementa todas las estrategias organizacionales y del negocio para el departamento, incluyendo la asignación de territorios ó productos, formulación de soluciones. | K33: Presidente | L33: Especialización | M33: Varias Especialidades (10 años) | N33: Dominarlo
A34: SGSC10 | B34: VICEPRESIDENTE SUSCRIPCIÓN | C34: SGSC10 | D34: 22 | E34: SERVICIOS FINANCIEROS Y SEGUROS | F34: SUSCRIPCION | G34: 0 | H34: 1 | I34: EJECUTIVOS SR | J34: Dirige y controla el proceso de Suscripción en los ramos de Personas, Auto, Patrimoniales y Riesgos industriales, a nivel nacional, velando porque se cumplan con las disposiciones legales establecidas por la Superintendencia de Seguros, las políticas y lineamientos de la organización y los condicionados de las pólizas, con la finalidad de controlar la siniestralidad y ofrecer una respuesta oportuna a los asegurados. | K34: Presidente | L34: Especialización | M34: Varias Especialidades (10 años) | N34: Dominarlo
A35: ATAT10 | B35: VICEPRESIDENTE TECNICO TELECOMINICACIONES | C35: ATAT10 | D35: 16 | E35: ALTA TECNOLOGÍA Y TELECOMUNICACIONES | F35: 0 | G35: 0 | H35: 1 | I35: EJECUTIVOS SR | J35: Planear y dirigir todo lo relacionado con el mantenimiento de la red nacional y de las estaciones de servicio. Definir estrategias a seguir para la elaboración de proyectos de construcción o ampliación de nuevas estaciones. | K35: Presidente | L35: Especialización | M35: Varias Especialidades (10 años) | N35: Dominarlo
A36: EDRT20 | B36: VICERECTOR ACADEMICO | C36: EDRT20 | D36: 20 | E36: SERVICIOS EDUCATIVOS | F36: RECTORIA | G36: SERVICIOS EDUCATIVOS | H36: 2 | I36: EJECUTIVOS | J36: Definir las políticas académicas de la institución, velando por la calidad de los programas que se ofrecen, así mismo, dirigir programas para la actualización docente, supervisar la creación de programas tanto de pregrado como de postgrado, certificar los reportes académicos ante el ICFES. | K36: Rector | L36: Especialización | M36: Más de 10 años | N36: Dominarlo
A37: COSC22 | B37: VICEPRESIDENTE SERVICIO AL CLIENTE | C37: COSC22 | D37: 3 | E37: COMERCIAL | F37: SERVICIO AL CLIENTE | G37: SERVICIO AL CLIENTE | H37: 2 | I37: EJECUTIVOS | J37: Definir las políticas de trabajo y los planes de acción necesarios, en la búsqueda del mejoramiento continuo de los índices de gestión de calidad de atención del cliente externo. | K37: Presidente / Gerente general | L37: Especialización | M37: Varias Especialidades (10 años) | N37: Dominarlo
A38: GHGN20 | B38: VICEPRESIDENTE GESTION HUMANA | C38: GHGN20 | D38: 6 | E38: GESTIÓN HUMANA | F38: GENERAL | G38: RECURSOS HUMANOS | H38: 2 | I38: EJECUTIVOS | J38: Formular y controlar el cumplimiento de políticas de administración de Recursos Humanos. Asesorar al gerente en materia de selección, evaluación del desempeño, administración salarial, bienestar social y relaciones laborales a fin de garantizar el desarrollo del recurso humano. | K38: Presidente | L38: Especialización | M38: Varias Especialidades (10 años) | N38: Dominarlo
A39: MKMP20 | B39: VICEPRESIDENTE MERCADEO | C39: MKMP20 | D39: 12 | E39: MERCADEO | F39: MARCAS Y PRODUCTOS | G39: MERCADEO | H39: 2 | I39: EJECUTIVOS | J39: Dirigir, planear y coordinar la ejecución de las estrategias de mercadeo para la compañía, garantizando que los productos y servicios sean de buena calidad y aceptación, procurar que su rentabilidad y permanencia sean adecuadas. | K39: Presidente / Gerente general | L39: Especialización | M39: Varias Especialidades (10 años) | N39: Dominarlo
A40: JULE20 | B40: GERENTE JURÍDICO CORPORATIVO | C40: JULE20 | D40: 8 | E40: JURÍDICA | F40: LEGAL | G40: LEGAL | H40: 2 | I40: EJECUTIVOS | J40: Responsable de la orientación legal de la compañía, asegurando la conformidad con la legislación actual, vigilando los derechos y obligaciones. Guía el trabajo de los abogados especializados y/o despachos de consultoría, incluyendo contratos, marcas y patentes. | K40: Vicepresidente jurídico | L40: Especialización | M40: Más de 10 años | N40: Dominarlo
A41: MAGN20 | B41: GERENTE TÉCNICO | C41: MAGN20 | D41: 11 | E41: MANUFACTURA E INDUSTRIA | F41: INGENIERIA | G41: INGENIERIA | H41: 2 | I41: EJECUTIVOS | J41: Responsable de establecer las especificaciones técnicas de los procesos, productos y/o servicios de la compañía para asegurar su aplicación, lo que implica dirigir las actividades de ingeniería, calidad, proyectos y otras actividades relacionadas. | K41: Gerente general | L41: Especialización | M41: Más de 10 años | N41: Dominarlo
A42: FIGN20 | B42: GERENTE ADMINISTRATIVO Y FINANCIERO | C42: FIGN20 | D42: 5 | E42: FINANCIERA | F42: GENERAL | G42: GENERAL | H42: 2 | I42: EJECUTIVOS | J42: Diseñar, direccionar, coordinar y controlar las políticas administrativas y financieras, supervisar y controlar los procesos productivos de los recursos financieros, humanos, de información y servicios generales para el cumplimiento de los objetivos empresariales. | K42: Vicepresidente administrativo | L42: Especialización | M42: Más de 10 años | N42: Dominarlo
A43: ADGN20 | B43: VICEPRESIDENTE ADMINISTRATIVO | C43: ADGN20 | D43: 1 | E43: ADMINISTRATIVA | F43: GENERAL | G43: GENERAL | H43: 2 | I43: EJECUTIVOS | J43: Diseñar, dirigir, coordinar y controlar las políticas administrativas, supervisar y controlar la estructura organizacional, procesos productivos del personal, presupuestos y seguros. Así mismo vela por la optimización tecnológica o informática y busca el mejoramiento del área de servicios generales, garantizar el cumplimiento de los objetivos de la empresa. | K43: Presidente | L43: Especialización | M43: Varias Especialidades (10 años) | N43: Dominarlo
A44: LSGN20 | B44: VICEPRESIDENTE LOGÍSTICA | C44: LSGN20 | D44: 10 | E44: LOGÍSTICA Y SUMINISTROS | F44: GENERAL | G44: GENERAL | H44: 2 | I44: EJECUTIVOS | J44: Responsable de las estrategias de logística de la empresa a nivel nacional o local, con base en la orientaciones del Presidente / Gerente General. Define las políticas de gastos del área de logística; Señala las políticas para el suministro de materias primas, productos o servicios, manejo de los inventarios y suministro de productos a los clientes. Establece las políticas y normas para la selección de proveedores a nivel nacional e internacional. Se requiere un profesional con postgrado en un área afín a su cargo y amplia experiencia en su campo. Reporta a: Presidente. | K44: Presidente | L44: Especialización | M44: Varias Especialidades (10 años) | N44: Dominarlo
A45: FQCH20 | B45: GERENTE GRUPO PRODUCTOS - HOSPITAL /ESPECIALIDADES | C45: FQCH20 | D45: 21 | E45: QUÍMICO Y FARMA | F45: HOSPITALARIA | G45: Farmacéutica | H45: 2 | I45: EJECUTIVOS | J45: Responsable de la planeación, coordinación y definición de los objetivos de venta, estrategias de mercadotecnia, análisis de rentabilidad, potencial de mercado, competencia, promoción y otras actividades de mercadotecnia para un grupo de productos Hospitalarios. | K45: Gerente general | L45: Especialización | M45: Más de 10 años | N45: Dominarlo
A46: FQCF20 | B46: GERENTE MEDICO GRUPO PRODUCTOS | C46: FQCF20 | D46: 21 | E46: QUÍMICO Y FARMA | F46: COMERCIAL FARMA | G46: Farmacéutica | H46: 2 | I46: EJECUTIVOS | J46: Responsable de la implementación de procedimientos para la revisión científica del material de mercadotecnia, etiquetas, protocolos y estudios para un grupo o línea de productos. Puede actuar como representante de la compañía, de esta línea específica de productos. | K46: Vicepresidente médico | L46: Especialización | M46: Más de 10 años | N46: Dominarlo
A47: CPPL20 | B47: VICEPRESIDENTE PLANEACION | C47: CPPL20 | D47: 4 | E47: CORPORATIVO | F47: PLANEACION | G47: CORPORATIVO | H47: 2 | I47: EJECUTIVOS | J47: Definir estrategias para la organización, evaluar opciones de crecimiento; coordinar las actividades de banca de inversión y seguir de cerca los intereses de la organización en otras empresas. Dirigir y coordinar la realización de proyectos desde el análisis de tecnología hasta el desarrollo de nuevos productos y/o servicios. | K47: Presidente | L47: Especialización | M47: Varias Especialidades (10 años) | N47: Dominarlo
... A49: AAAU20 | B49: VICEPRESIDENTE CONTRALOR | C49: AAAU20 | D49: 2 | E49: AUDITORIA | F49: AUDITORIA | G49: AUDITORIA | H49: 2 | I49: EJECUTIVOS | J49: Coordinar, dirigir y controlar las normas procedimientos y flujo de información contable y financiera tendientes a proteger en forma adecuada los activos e intereses económicos de la entidad. Asesorar a los demás ejecutivos en cuanto a procedimientos, control y manejo de sus áreas para el buen funcionamiento de las mismas. | K49: Presidente | L49: Especialización | M49: Varias Especialidades (10 años) | N49: Dominarlo
A50: HEPE20 | B50: GERENTE PERFORACION | C50: HEPE20 | D50: 23 | E50: MINERIA, ENERGIA E HIDROCARBUROS | F50: PERFORACION | G50: 0 | H50: 2 | I50: EJECUTIVOS | J50: Diseñar, planear y coordinar las actividades del programa de perforación con el fin de alcanzar éxito económico en las operaciones y el logro de los objetivos empresariales. | K50: Gerente general | L50: Especialización | M50: Más de 10 años | N50: Dominarlo
A51: SGSC20 | B51: VICEPRESIDENTE SUSCRIPCIÓN | C51: SGSC20 | D51: 22 | E51: SERVICIOS FINANCIEROS Y SEGUROS | F51: SUSCRIPCION | G51: 0 | H51: 2 | I51: EJECUTIVOS | J51: Diseñar e implementar las políticas y estratégias de comercialización y suscripción de las diferentes ramas de seguros, desarrolla productos y busca optimizar los servicios a los clientes con el objetivo de alcanzar las metas establecidas por la dirección general. | K51: Presidente | L51: Especialización | M51: Varias Especialidades (10 años) | N51: Dominarlo
A52: SGID20 | B52: VICEPRESIDENTE TECNICO INDEMNIZACIONES | C52: SGID20 | D52: 22 | E52: SERVICIOS FINANCIEROS Y SEGUROS | F52: INDEMNIZACIONES | G52: 0 | H52: 2 | I52: EJECUTIVOS | J52: Asegurar el cumplimiento de los estándares corporativos relacionados con: servicio, constitutivos de reservas, pagos de indemnizaciones, ajustes, investigación y administración de asesores externos. Es responsable por la planeación dirección y control de las operaciones, así como la adecuada documentación de reclamos. Se encarga de asegurar el control y eficacia de las acciones de recobros y de la conservación y renta de salvamentos. Representa a la compañía en cualquier proceso legal originado en las actividades de reclamaciones. | K52: Presidente | L52: Especialización | M52: Varias Especialidades (10 años) | N52: Dominarlo
A53: COVS30 | B53: GERENTE COMERCIAL | C53: COVS30 | D53: 3 | E53: COMERCIAL | F53: VENTAS | G53: VENTAS | H53: 3 | I53: GERENTES SR | J53: Planear, dirigir y controlar una línea específica de productos, evaluar el grado de satisfacción del consumidor. Dar apoyo en la fijación de políticas de comercialización. | K53: Vicepresidente comercial/Gerente general | L53: Especialización | M53: Especializada (7 a 9 años) | N53: Dominarlo
A54: COSC33 | B54: GTE TELEMARKETING | C54: COSC33 | D54: 3 | E54: COMERCIAL | F54: SERVICIO AL CLIENTE | G54: TELEMARKETING | H54: 3 | I54: GERENTES SR | J54: Gerencia la ejecución de las actividades en la unidad de telemarketing pasivo, que brinda atención a clientes en asuntos ligados a los productos y servicios comercializados por la empresa. Gerencia, además, procesos de telemarketing activo, buscando conseguir nuevos clientes, de acuerdo con la política comercial preestablecida. Desarrolla el equipo de operadores, buscando capacitarlos para dar una correcta atención al cliente, así como para optimizar la política de expansión y conquista de nuevos clientes y el grado del relación cliente-empresa. | K54: Vicepresidente Servicio al cliente | L54: Especialización | M54: Especializada (7 a 9 años) | N54: Dominarlo
A55: GHSE30 | B55: GERENTE RECLUTAMIENTO Y SELECCIÓN | C55: GHSE30 | D55: 6 | E55: GESTIÓN HUMANA | F55: SELECCION | G55: SELECCION | H55: 3 | I55: GERENTES SR | J55: Responsable de las definiciones y estrategias del área de reclutamiento y selección, con el objetivo de atraer a profesionales competentes y preparados, identificando, interna y externamente, los recursos humanos adecuados para ocupar las posiciones solicitadas. | K55: Gerente Gestión Humana | L55: Especialización | M55: Especializada (7 a 9 años) | N55: Dominarlo
A56: JUSG30 | B56: SECRETARIO GENERAL | C56: JUSG30 | D56: 8 | E56: JURÍDICA | F56: SECRETARIA GENERAL | G56: SECRETARIA GENERAL | H56: 3 | I56: GERENTES SR | J56: Apoyar y coordinar los aspectos administrativos tanto de la Junta Directiva como de la Asamblea General de Accionistas, elaborar la documentación y actas correspondientes bajo las normas legales y estatutarias que rigen la entidad. | K56: Presidente | L56: Especialización | M56: Especializada (7 a 9 años) | N56: Dominarlo
A57: FISR30 | B57: GERENTE RIESGOS | C57: FISR30 | D57: 5 | E57: FINANCIERA | F57: SEGUROS / RIESGO FINANCIERO | G57: RIESGO | H57: 3 | I57: GERENTES SR | J57: Planear, dirigir, coordinar y controlar las políticas de riesgo de mercado en el corto, mediano y largo plazo, teniendo en cuenta las variables y análisis técnicos y fundamentales del mercado, con el fin de recomendar los instrumentos de inversión para maximizar el valor de los accionistas. | K57: Vicepresidente de Gerenciamiento del riesgo | L57: Especialización | M57: Especializada (7 a 9 años) | N57: Dominarlo
A58: TIIR30 | B58: GTE INFRAESTRUCTURA | C58: TIIR30 | D58: 9 | E58: TECNOLOGÍA E INFORMÁTICA | F58: INFRAESTRUCTURA REDES BASES DATOS | G58: REDES BASES DE DATOS | H58: 3 | I58: GERENTES SR | J58: Responde por el planeamiento, desarrollo y control de las redes de telecomunicaciones (voz, datos y mensajes). Dimensiona la capacidad de operación de la red dentro de los niveles de performance y calidad establecidos. Coordina la alocación de los recursos de telecomunicaciones de acuerdo con las necesidades de cada segmento de la empresa. Controla la calidad de los canales y la correcta observación de los estándares y procedimientos definidos. Evalúa riesgos y establece los planes de contingencia de la unidad. | K58: Vicepresidente sistemas / Gerente general | L58: Especialización | M58: Especializada (7 a 9 años) | N58: Dominarlo
A59: GHGN30 | B59: GERENTE GESTION HUMANA | C59: GHGN30 | D59: 6 | E59: GESTIÓN HUMANA | F59: GENERAL | G59: RECURSOS HUMANOS | H59: 3 | I59: GERENTES SR | J59: Planear, dirigir y evaluar las políticas de administración de personal, capacitación, desarrollo y bienestar. Asesorar a los demás ejecutivos en lo pertinente a su área y supervisar a los ejecutivos de recursos humanos de cada una de las plantas o filiales de su organización. | K59: Presidente / Gerente general | L59: Especialización | M59: Especializada (7 a 9 años) | N59: Dominarlo
A60: IDPR30 | B60: GERENTE DESARROLLO PRODUCTOS | C60: IDPR30 | D60: 7 | E60: I & D | F60: DESARROLLO DE PRODUCTOS | G60: PRODUCTOS | H60: 3 | I60: GERENTES SR | J60: Responsable de las actividades relacionadas con el desarrollo de un producto o línea de productos, así como de las mejoras a los productos y tecnologías existentes. Da seguimiento junto con la casa matriz a la evolución tecnológica y evalúa las posibilidad de implementacion. | K60: Gerente Investigación y Desarrollo | L60: Especialización | M60: Especializada (7 a 9 años) | N60: Dominarlo
...

Sheet HOMOLOGACIÓN
C2: Cargo Valorado | D2: Cargo Homologado 1 | E2: Descripción 1 | F2: Cargo Homologado 2 | G2: Descripción 2 | H2: Observaciones
E3: =IFERROR(VLOOKUP(Tabla1[[#This Row],[Cargo Homologado 1]],'[1]catalogo '!$b$1:$J$1052,9,0)," ") | G3: =IFERROR(VLOOKUP(Tabla1[[#This Row],[Cargo Homologado 2]],'[1]catalogo '!$b$1:$J$1052,9,0)," ")
E4: =IFERROR(VLOOKUP(Tabla1[[#This Row],[Cargo Homologado 1]],'[1]catalogo '!$b$1:$J$1052,9,0)," ") | G4: =IFERROR(VLOOKUP(Tabla1[[#This Row],[Cargo Homologado 2]],'[1]catalogo '!$b$1:$J$1052,9,0)," ")

Sheet Plantilla de Homologación
D1: {=INDIRECT(VLOOKUP(#ref!,CATALOGO!$AE$3:$AG$29,3,0))} -> #NAME? | E1: =IFERROR(VLOOKUP(F3,CATALOGO!$AJ$2:$AM$27,4,0),"") -> Vicepresidente / Director Región / Presidente País
B2: NOMBRE CARGO | C2: AREA EMPRESA | D2: CARGO HOMOLOGADO | E2: PISTA | F2: CAT
E3: =IFERROR(VLOOKUP(F3,CATALOGO!$AJ$2:$AM$27,4,0),"") -> Vicepresidente / Director Región / Presidente País | F3: 20
E4: =IFERROR(VLOOKUP(F4,CATALOGO!$AJ$2:$AM$27,4,0),"") -> Gerente / Gerente Región / Gerente País / Gerente Unidad de Negocio / Gerente de Cuenta | F4: 18
E5: =IFERROR(VLOOKUP(F5,CATALOGO!$AJ$2:$AM$27,4,0),"") -> Gerente / Gerente Región / Gerente País / Gerente Unidad de Negocio / Gerente de Cuenta | F5: 18
E6: =IFERROR(VLOOKUP(F6,CATALOGO!$AJ$2:$AM$27,4,0),"") -> Gerente / Gerente Región / Gerente País / Gerente Unidad de Negocio / Gerente de Cuenta | F6: 16
E7: =IFERROR(VLOOKUP(F7,CATALOGO!$AJ$2:$AM$27,4,0),"") -> Director / Jefe / Especialista Sr / Ingeniero / Ejecutivo de Cuenta | F7: 15
E8: =IFERROR(VLOOKUP(F8,CATALOGO!$AJ$2:$AM$27,4,0),"") -> Director / Jefe / Especialista Sr / Ingeniero / Ejecutivo de Cuenta | F8: 15
E9: =IFERROR(VLOOKUP(F9,CATALOGO!$AJ$2:$AM$27,4,0),"") -> Director / Jefe / Especialista Sr / Ingeniero / Ejecutivo de Cuenta | F9: 15
E10: =IFERROR(VLOOKUP(F10,CATALOGO!$AJ$2:$AM$27,4,0),"") -> Director / Jefe / Especialista Sr / Ingeniero / Ejecutivo de Cuenta | F10: 15
E11: =IFERROR(VLOOKUP(F11,CATALOGO!$AJ$2:$AM$27,4,0),"") -> Director / Jefe / Especialista Sr / Ingeniero / Ejecutivo de Cuenta | F11: 15
E12: =IFERROR(VLOOKUP(F12,CATALOGO!$AJ$2:$AM$27,4,0),"") -> Director / Jefe / Especialista Sr / Ingeniero / Ejecutivo de Cuenta | F12: 15
E13: =IFERROR(VLOOKUP(F13,CATALOGO!$AJ$2:$AM$27,4,0),"") -> Director / Jefe / Especialista Sr / Ingeniero / Ejecutivo de Cuenta | F13: 15
E14: =IFERROR(VLOOKUP(F14,CATALOGO!$AJ$2:$AM$27,4,0),"") -> Director / Jefe / Especialista Sr / Ingeniero / Ejecutivo de Cuenta | F14: 14
... E83: =IFERROR(VLOOKUP(F83,CATALOGO!$AJ$2:$AM$27,4,0),"") -> Auxiliar / Operario II / Representante de Ventas Sr | F83: 4
E84: =IFERROR(VLOOKUP(F84,CATALOGO!$AJ$2:$AM$27,4,0),"")
E85: =IFERROR(VLOOKUP(F85,CATALOGO!$AJ$2:$AM$27,4,0),"")
E86: =IFERROR(VLOOKUP(F86,CATALOGO!$AJ$2:$AM$27,4,0),"")
E87: =IFERROR(VLOOKUP(F87,CATALOGO!$AJ$2:$AM$27,4,0),"")
E88: =IFERROR(VLOOKUP(F88,CATALOGO!$AJ$2:$AM$27,4,0),"")
E89: =IFERROR(VLOOKUP(F89,CATALOGO!$AJ$2:$AM$27,4,0),"")
E90: =IFERROR(VLOOKUP(F90,CATALOGO!$AJ$2:$AM$27,4,0),"")
E91: =IFERROR(VLOOKUP(F91,CATALOGO!$AJ$2:$AM$27,4,0),"")
E92: =IFERROR(VLOOKUP(F92,CATALOGO!$AJ$2:$AM$27,4,0),"")
E93: =IFERROR(VLOOKUP(F93,CATALOGO!$AJ$2:$AM$27,4,0),"")
E94: =IFERROR(VLOOKUP(F94,CATALOGO!$AJ$2:$AM$27,4,0),"")
E95: =IFERROR(VLOOKUP(F95,CATALOGO!$AJ$2:$AM$27,4,0),"")
... E98: =IFERROR(VLOOKUP(F98,CATALOGO!$AJ$2:$AM$27,4,0),"")

Sheet LISTA
B3: NOMBRE | C3: NIVEL | D3: AREA GENERAL | E3: NOMBRE
B4: VICEPRESIDENTE ADMINISTRATIVO | C4: 2 | D4: ADMINISTRATIVA | E4: VICEPRESIDENTE ADMINISTRATIVO
B5: GERENTE ADMINISTRATIVO | C5: 3 | D5: ADMINISTRATIVA | E5: GERENTE ADMINISTRATIVO
B6: GERENTE SERVICIOS GENERALES | C6: 4 | D6: ADMINISTRATIVA | E6: GERENTE SERVICIOS GENERALES
B7: GERENTE SEGURIDAD FISICA | C7: 4 | D7: ADMINISTRATIVA | E7: GERENTE SEGURIDAD FISICA
B8: GERENTE PROYECTOS | C8: 4 | D8: ADMINISTRATIVA | E8: GERENTE PROYECTOS
B9: GERENTE ORGANIZACION Y METODOS | C9: 4 | D9: ADMINISTRATIVA | E9: GERENTE ORGANIZACION Y METODOS
B10: GERENTE INFRAESTRUCTURA FISICA | C10: 4 | D10: ADMINISTRATIVA | E10: GERENTE INFRAESTRUCTURA FISICA
B11: GERENTE INMUEBLES | C11: 4 | D11: ADMINISTRATIVA | E11: GERENTE INMUEBLES
B12: JEFE MANTENIMIENTO EDIFICACIONES | C12: 5 | D12: ADMINISTRATIVA | E12: JEFE MANTENIMIENTO EDIFICACIONES
B13: JEFE PROYECTO | C13: 5 | D13: ADMINISTRATIVA | E13: JEFE PROYECTO
B14: JEFE PROCESOS | C14: 5 | D14: ADMINISTRATIVA | E14: JEFE PROCESOS
B15: JEFE ORGANIZACION Y METODOS | C15: 5 | D15: ADMINISTRATIVA | E15: JEFE ORGANIZACION Y METODOS
... B1053: ANALISTA DESARROLLO REDES | C1053: 7 | D1053: VEHÍCULOS Y PARTES | E1053: ANALISTA DESARROLLO REDES

Sheet CATALOGO
B2: ADMINISTRATIVA | C2: AGROINDUSTRIA Y PECUARIO | D2: ALTA TECNOLOGÍA Y TELECOMUNICACIONES | E2: AUDITORIA | F2: COMERCIAL | G2: CONSTRUCCIÓN E INSUMOS | H2: CONSUMO MASIVO | I2: CORPORATIVO | J2: FINANCIERA | K2: GESTIÓN HUMANA | L2: HOTELERIA TURISMO Y RECREACIÓN | M2: I & D | N2: JURÍDICA | O2: LOGÍSTICA Y SUMINISTROS | P2: MANUFACTURA E INDUSTRIA | Q2: MEDIOS | R2: MERCADEO | S2: MINERIA, ENERGIA E HIDROCARBUROS | T2: OPERACIONES | U2: OPERARIOS | V2: QUÍMICO Y FARMA | W2: SERVICIOS DE SALUD | X2: SERVICIOS EDUCATIVOS | Y2: SERVICIOS FINANCIEROS Y SEGUROS | Z2: TECNOLOGÍA E INFORMÁTICA | AA2: TEXTILES CONFECCIONES Y CALZADO | AB2: VEHÍCULOS Y PARTES | AJ2: CATEGORIA | AK2: RUTA CARRERA GERENCIAL | AL2: RUTA CARRERA CONTRIBUCION INDIVIDUAL | AM2: PISTA
B3: VICEPRESIDENTE ADMINISTRATIVO | C3: GERENTE CULTIVO | D3: VICEPRESIDENTE CONSULTORÍA TI | E3: VICEPRESIDENTE CONTRALOR | F3: VICEPRESIDENTE COMERCIAL | G3: GERENTE CONSTRUCCIONES | H3: VICEPRESIDENTE CATEGORÍA | I3: PRESIDENTE - REGIONAL | J3: VICEPRESIDENTE GERENCIAMENTO RIESGO | K3: VICEPRESIDENTE GESTION HUMANA | L3: JEFE RESERVAS Y/O HABITACIONES | M3: GERENTE DESARROLLO PRODUCTOS | N3: VICEPRESIDENTE JURIDICO | O3: VICEPRESIDENTE INTERNACIONAL | P3: VICEPRESIDENTE MANUFACTURA | Q3: DIRECTOR MEDIO COMUNICACIÓN | R3: VICEPRESIDENTE MERCADEO | S3: GERENTE PERFORACION | T3: VICEPRESIDENTE OPERACIONES | U3: CONDUCTOR VEHÍCULO PESADO | V3: VICEPRESIDENTE INVESTIGACIÓN CLÍNICA | W3: DIRECTOR CIENTÍFICO (CLÍNICA U HOSPITAL) | X3: RECTOR | Y3: VICEPRESIDENTE SINIESTROS | Z3: VICEPRESIDENTE SISTEMAS | AA3: JEFE DISEÑO | AB3: GERENTE DESARROLLO REDES | AE3: ADMINISTRATIVA | AF3: B | AG3: ="CATALOGO!$"&AF3&"$3:$"&AF3&"$155" -> CATALOGO!$B$3:$B$155 | AJ3: 25 | AK3: Presidente Global | AM3: =IF(AK3="","",AK3)&IF(OR(AL3="",AK3=""),""," / ")&AL3 -> Presidente Global
B4: GERENTE ADMINISTRATIVO | C4: AGRONOMO | D4: VICEPRESIDENTE VENTAS ALTA TECNOLOGÍA (GENÉRICO) | E4: GERENTE AUDITORIA INTERNA | F4: VICEPRESIDENTE SERVICIOS AL CLIENTE | G4: DIRECTOR PROYECTO | H4: GERENTE CATEGORÍA | I4: GERENTE GENERAL | J4: DIRETOR RELACIONES CON INVERSIONISTAS | K4: GERENTE RECLUTAMIENTO Y SELECCIÓN | L4: GERENTE ALIMENTOS Y BEBIDAS | M4: GERENTE INVESTIGACIÓN Y DESARROLLO | N4: GERENTE JURÍDICO CORPORATIVO | O4: VICEPRESIDENTE LOGÍSTICA | P4: VICEPRESIDENTE MANUFACTURA | Q4: SUBDIRECTOR MEDIO COMUNICACIÓN | R4: GERENTE MERCADEO | S4: GERENTE INGENIERIA | T4: GERENTE OPERACIONES | U4: TÉCNICO MECÁNICO II | V4: VICEPRESIDENTE MEDICO | W4: DIRECTOR MEDICO SERVICIOS SALUD | X4: VICERECTOR ACADEMICO | Y4: VICEPRESIDENTE UNIDAD NEGOCIO - GENERALES | Z4: GTE INFRAESTRUCTURA | AA4: DISEÑADORA MODAS | AB4: GERENTE SERVICIOS/GARANTÍA | AE4: AGROINDUSTRIA Y PECUARIO | AF4: C | AG4: ="CATALOGO!$"&AF4&"$3:$"&AF4&"$155" -> CATALOGO!$C$3:$C$155 | AJ4: 24 | AK4: Presidente Regional | AM4: =IF(AK4="","",AK4)&IF(OR(AL4="",AK4=""),""," / ")&AL4 -> Presidente Regional
B5: GERENTE SERVICIOS GENERALES | C5: JEFE POSTCOSECHA | D5: VICEPRESIDENTE TECNICO TELECOMINICACIONES | E5: JEFE CUMPLIMIENTO | F5: GERENTE UNIDAD NEGOCIO | G5: DIRECTOR DISEÑO | H5: GERENTE TRADE MKARKETING | I5: PRESIDENTE PAIS | J5: VICEPRESIDENTE FINANCIERO | K5: GERENTE GESTION HUMANA | L5: JEFE MANTENIMIENTO (SERVICIOS) | M5: GERENTE DESARROLLO EMPAQUES | N5: SECRETARIO GENERAL | O5: GERENTE NEGOCIOS INTERNACIONALES | P5: VICEPRESIDENTE INDUSTRIAL | Q5: JEFE REDACCION | R5: GTE CANALES ALTERNATIVOS | S5: GERENTE PROYECTOS - HIDROCARBUROS | T5: JEFE /COORDINADOR OPERACIONES | U5: OPERADOR MAQUINARIA ESPECIALIZADA | V5: GERENTE GRUPO PRODUCTOS - HOSPITAL /ESPECIALIDADES | W5: MEDICO SUB ESPECIALISTA | X5: DIRECTOR POSTGRADO | Y5: VICEPRESIDENTE COMERCIAL CANAL RETAIL | Z5: GERENTE SISTEMAS | AA5: COORDINADOR DE CORTE | AB5: JEFE ./COORDINADOR/ESP. DESARROLLO REDES | AE5: ALTA TECNOLOGÍA Y TELECOMUNICACIONES | AF5: D | AG5: ="CATALOGO!$"&AF5&"$3:$"&AF5&"$155" -> CATALOGO!$D$3:$D$155 | AJ5: 23 | AK5: Presidente Pais | AM5: =IF(AK5="","",AK5)&IF(OR(AL5="",AK5=""),""," / ")&AL5 -> Presidente Pais
B6: GERENTE SEGURIDAD FISICA | C6: ADMINISTRADOR GRANJAS | D6: CONSULTOR CONTRATOS, LICIT. Y PROPUESTAS - ESPEC./S | E6: JEFE AUDITORIA INTERNA | F6: VICEPRESIDENTE DESARROLLO NEGOCIOS | G6: GERENTE TÉCNICO - CONSTRUCCIONES | H6: JEFE CATEGORÍA | I6: PRESIDENTE/ GERENTE GENERAL - PAIS | J6: VICEPRESIDENTE CREDITO | K6: GERENTE RELACIONES LABORALES/SINDICALES | L6: JEFE ALIMENTOS Y BEBIDAS | M6: JEFE INVESTIGACION Y DESARROLLO | N6: GERENTE JURIDICO | O6: GERENTE OPERACIONES INTERNACIONALES | P6: VICEPRESIDENTE TÉCNICO | Q6: COORDINADOR COPRODUCCION Y ALIANZAS CONTENIDO | R6: GERENTE PUBLICIDAD | S6: DIRECTOR HSEQ | T6: ANALISTA OPERACIONES | U6: OPERARIO MONTACARGA | V6: GERENTE MEDICO GRUPO PRODUCTOS | W6: AUDITOR ODONTOLOGIA / MEDICO | X6: RECTOR COLEGIO | Y6: VICEPRESIDENTE SINIESTROS ARP | Z6: GERENTE OPERACIÓN SISTEMAS | AA6: PATRONISTA | AB6: COORDINADOR/JEFESERVICIOS/GARANTÍA | AE6: AUDITORIA | AF6: E | AG6: ="CATALOGO!$"&AF6&"$3:$"&AF6&"$155" -> CATALOGO!$E$3:$E$155 | AJ6: 22 | AK6: Vicepresidente / Director Región / Presidente País | AM6: =IF(AK6="","",AK6)&IF(OR(AL6="",AK6=""),""," / ")&AL6 -> Vicepresidente / Director Región / Presidente País
B7: GERENTE PROYECTOS | C7: DIRECTOR INCUBACIÓN | D7: DIRECTOR DESARROLLO | E7: AUDITOR | F7: VICEPRESIDENTE SERVICIO AL CLIENTE | G7: DIRECTOR OBRA | H7: COORDINADOR PROMOCIÓN Y MERCHANDISING | I7: VICEPRESIDENTE EJECUTIVO | J7: GERENTE ADMINISTRATIVO Y FINANCIERO | K7: GERENTE CAPACITACIÓN Y DESARROLLO | L7: JEFE BANQUETES | M7: DIBUJANTE TÉCNICO PL. | N7: CONSULTOR/COORDINADOR/ESPEC. JURÍDICO | O7: GERENTE REGULATORIO | P7: GERENTE TÉCNICO | Q7: ANALISTA CONTENIDOS | R7: DIRECTOR DE LÍNEA O MARCA | S7: JEFE CONSTRUCCIONES Y OBRAS CIVILES | T7: ASISTENTE OPERACIONES | U7: PINTOR | V7: GERENTE FARMACOVIGILÂNCIA | W7: CIRUJANO ESPECIALIZADO | X7: DIRECTOR INVESTIGACIÓN | Y7: VICEPRESIDENTE SUSCRIPCIÓN | Z7: GERENTE HELPDESK | AA7: AUXILIAR CORTE | AB7: ANALISTA GARANTÍA | AE7: COMERCIAL | AF7: F | AG7: ="CATALOGO!$"&AF7&"$3:$"&AF7&"$155" -> CATALOGO!$F$3:$F$155 | AJ7: 21 | AK7: Vicepresidente / Director Región / Presidente País | AM7: =IF(AK7="","",AK7)&IF(OR(AL7="",AK7=""),""," / ")&AL7 -> Vicepresidente / Director Región / Presidente País
B8: GERENTE ORGANIZACION Y METODOS | C8: DIRECTOR POLLO ENGORDE | D8: DIRECTOR NACIONAL CENTROS SERVICIO | E8: AUDITOR SISTEMAS | F8: GERENTE COMERCIAL | G8: DIRECTOR OBRA - INTERVENTOR | H8: JEFE CAJEROS VENTAS | I8: VICEPRESIDENTE PLANEACION ESTRATÉGICA | J8: GERENTE RIESGOS | K8: GERENTE COMUNICACIÓN INTERNA | L8: JEFE LAVANDERÍA | M8: INGENIERO DESARROLLO PRODUCTOS | N8: DIRECTOR JURIDICO | O8: GERENTE DESARROLLO PROVEEDORES | P8: GERENTE PRODUCCION | Q8: EDITOR GRAFICO | R8: GERENTE GRUPO PRODUCTOS | S8: SUPERINTENDENTE CAMPO | U8: PLOMERO | V8: GERENTE GRUPO PRODUCTOS LÍNEA ÉTICA | W8: CIRUJANO GENERAL | X8: DECANO TIPO A | Y8: GTE SR COMERCIAL CANAL RETAIL | Z8: DIRECTOR DETENCION Y PREVENCION FRAUDES | AB8: ANALISTA DESARROLLO REDES | AE8: CONSTRUCCIÓN E INSUMOS | AF8: G | AG8: ="CATALOGO!$"&AF8&"$3:$"&AF8&"$155" -> CATALOGO!$G$3:$G$155 | AJ8: 20 | AK8: Vicepresidente / Director Región / Presidente País | AM8: =IF(AK8="","",AK8)&IF(OR(AL8="",AK8=""),""," / ")&AL8 -> Vicepresidente / Director Región / Presidente País
B9: GERENTE INFRAESTRUCTURA FISICA | C9: DIRECTOR PRODUCCIÓN POLLO | D9: DIRECTOR NACIONAL SERVICIOS | E9: ANALISTA CUMPLIMIENTO | F9: GTE TELEMARKETING | G9: DIRECTOR TRAMITES | H9: JEFE SECCIÓN VENTAS | I9: VICEPRESIDENTE PLANEACION | J9: GERENTE INVERSIONES | K9: GERENTE COMPENSACIÓN | L9: CHEFF EJECUTIVO | M9: INGENIERO DESARROLLO EMPAQUES - ESPECIALISTA | N9: JEFE DIVISION JURIDICA | O9: GERENTE PLANEACION LOGÍSTICA | P9: GERENTE PROCESOS | Q9: EDITOR SECCION | R9: GERENTE PRODUCTO ESPECIALIZADO | S9: SUPERINTENDENTE PRODUCCIÓN | U9: SOLDADOR | V9: DIRECTOR MEDICO COMERCIAL | W9: ENFERMERA JEFE | X9: DIRECTOR ACADEMICO - COLEGIO | Y9: VICEPRESIDENTE SUSCRIPCIÓN | Z9: GERENTE SEGURIDAD SISTEMAS | AE9: CONSUMO MASIVO | AF9: H | AG9: ="CATALOGO!$"&AF9&"$3:$"&AF9&"$155" -> CATALOGO!$H$3:$H$155 | AJ9: 19 | AK9: Gerente / Gerente Región / Gerente País / Gerente Unidad de Negocio | AM9: =IF(AK9="","",AK9)&IF(OR(AL9="",AK9=""),""," / ")&AL9 -> Gerente / Gerente Región / Gerente País / Gerente Unidad de Negocio
B10: GERENTE INMUEBLES | C10: JEFE LEVANTE | D10: DIRECTOR OPERACIONES (TELECOMUNICACIONES) | E10: ASISTENTE AUDITORIA | F10: GERENTE DESARROLLO NEGOCIOS | G10: INGENIERO OBRA | H10: JEFE TRADE MKARKETING | I10: GERENTE GOBIERNO CORPORATIVO | J10: GERENTE FINANCIERO | K10: JEFE SELECCION | L10: GERENTE ALIMENTOS Y BEBIDAS | M10: ANALISTA INVESTIGACION Y DESARROLLO PRODUCTOS | N10: ASESOR LEGAL | O10: GERENTE MATERIALES | P10: GERENTE PLANEACION Y CONTROL PRODUCCIÓN | Q10: PERIODISTA SENIOR | R10: JEFE /COORDINADOR/ESPEC. PUBLICIDAD | S10: INGENIERO PRODUCCION - PETROLEOS | U10: OPERADOR III | V10: GERENTE INVESTIGACIÓN CLÍNICA | W10: JEFE ADMISIONES | X10: DIRECTOR ADMISIONES - EDUCACIÓN | Y10: VICEPRESIDENTE TECNICO INDEMNIZACIONES | Z10: DIRECTOR INGENIERIA E INFRAESTRUCTURA | AE10: CORPORATIVO | AF10: I | AG10: ="CATALOGO!$"&AF10&"$3:$"&AF10&"$155" -> CATALOGO!$I$3:$I$155 | AJ10: 18 | AK10: Gerente / Gerente Región / Gerente País / Gerente Unidad de Negocio | AL10: Gerente de Cuenta | AM10: =IF(AK10="","",AK10)&IF(OR(AL10="",AK10=""),""," / ")&AL10 -> Gerente / Gerente Región / Gerente País / Gerente Unidad de Negocio / Gerente de Cuenta
B11: JEFE MANTENIMIENTO EDIFICACIONES | C11: SUPERVISOR CAMPO | D11: DIRECTOR PLANEACION TECNICA | E11: AUXILIAR CUMPLIMIENTO | F11: GTE CALL CENTER | G11: INGENIERO RESIDENTE | H11: SUPERVISOR PROMOTORES Y MERCADERISTAS | I11: GERENTE PLANEACION | J11: GERENTE CRÉDITO Y COBRANZA | K11: JEFE SALUD OCUPACIONAL | L11: JEFE RECEPCION | M11: DISEÑADOR INDUSTRIAL | N11: ABOGADO | O11: GERENTE CONTROL INVENTARIOS | P11: GERENTE TECNICO | Q11: REDACTOR | R11: JEFE /COORDINADOR/ESPEC. MARKETING | S11: SUPERINTENDENTE CAMPO | U11: TÉCNICO ELECTRICISTA INDUSTRIAL II | V11: GERENTE PRODUCTO - HOSPITAL /ESPECIALIDADES | W11: JEFE ATENCIÓN MÉDICA | X11: DIRECTOR BIBLIOTECA | Y11: GERENTE OPERACIONES BANCARIAS | Z11: GERENTE PROYECTOS SISTEMAS | AE11: FINANCIERA | AF11: J | AG11: ="CATALOGO!$"&AF11&"$3:$"&AF11&"$155" -> CATALOGO!$J$3:$J$155 | AJ11: 17 | AK11: Gerente / Gerente Región / Gerente País / Gerente Unidad de Negocio | AL11: Gerente de Cuenta | AM11: =IF(AK11="","",AK11)&IF(OR(AL11="",AK11=""),""," / ")&AL11 -> Gerente / Gerente Región / Gerente País / Gerente Unidad de Negocio / Gerente de Cuenta
B12: JEFE PROYECTO | C12: SUPERVISOR CULTIVO | D12: DIRECTOR TERMINALES CELULARES | E12: AUXILIAR AUDITORIA | F12: GERENTE ADMINISTRACIÓN VENTAS | G12: ARQUITECTO | H12: ADMINISTRADOR DROGUERÍA | I12: JEFE GOBIERNO CORPORATIVO | J12: GERENTE TESORERIA - TESORERO | K12: JEFE GESTION HUMANA | L12: JEFE SEGURIDAD HOTELERA | N12: ABOGADO JUNIOR | O12: GERENTE LOGISTICA | P12: GERENTE FABRICA O PLANTA | Q12: FOTOMECANICO | R12: JEFE MERCADEO | S12: COORDINADOR RELACIONES CON LA COMUNIDAD | U12: TÉCNICO ELECTRÓNICA II | V12: GERENTE PRODUCTO JR. LÍNEA ÉTICA | W12: JEFE DEPARTAMENTO MÉDICO | X12: JEFE CREDITOS EDUCATIVOS Y CARTERA | Y12: GERENTE FINANZAS | Z12: GERENTE OPERACIONES / PROCESAMIENTO INFORMACIÓN | AE12: GESTIÓN HUMANA | AF12: K | AG12: ="CATALOGO!$"&AF12&"$3:$"&AF12&"$155" -> CATALOGO!$K$3:$K$155 | AJ12: 16 | AK12: Gerente / Gerente Región / Gerente País / Gerente Unidad de Negocio | AL12: Gerente de Cuenta | AM12: =IF(AK12="","",AK12)&IF(OR(AL12="",AK12=""),""," / ")&AL12 -> Gerente / Gerente Región / Gerente País / Gerente Unidad de Negocio / Gerente de Cuenta
B13: JEFE PROCESOS | C13: SUPERVISOR RIEGO | D13: DIRECTOR TRANSMISIONES | F13: GERENTE VENTAS | G13: INGENIERO DISEÑO | H13: ADMINISTRADOR SUPERMERCADO | I13: GERENTE RELACIONES PUBLICAS - COMUNIC. | J13: GERENTE PRESUPUESTO | K13: JEFE CAPACITACION | L13: ASISTENTE RESERVAS Y/O HABITACIONES | O13: GERENTE DISTRIBUCIÓN | P13: GERENTE MEDIO AMBIENTE | Q13: PERIODISTA JUNIOR | R13: GERENTE PRODUCTO | S13: INGENIERO GEOLOGO | U13: ALMACENISTA PRODUCCIÓN | V13: DIRECTOR TÉCNICO | W13: JEFE INFORMACIÓN Y ESTADÍSTICA | X13: DIRECTOR DE OFICINA DE PUBLICACIONES | Y13: GERENTE FIDUCIA ADMINISTRACION Y PAGO | Z13: GERENTE SOPORTE Y TECNOLOGIA | AE13: HOTELERIA TURISMO Y RECREACIÓN | AF13: L | AG13: ="CATALOGO!$"&AF13&"$3:$"&AF13&"$155" -> CATALOGO!$L$3:$L$155 | AJ13: 15 | AK13: Director / Jefe | AL13: Especialista Sr / Ingeniero / Ejecutivo de Cuenta | AM13: =IF(AK13="","",AK13)&IF(OR(AL13="",AK13=""),""," / ")&AL13 -> Director / Jefe / Especialista Sr / Ingeniero / Ejecutivo de Cuenta
B14: JEFE ORGANIZACION Y METODOS | C14: COORDINADOR INCUBACIÓN | D14: GERENTE ESTADISTICAS E INFORMACION | F14: GERENTE SERVICIO AL CLIENTE | G14: INGENIERO CONTROL DE COSTOS | H14: ANALISTA TRADE MKARKETING | I14: JEFE COORDINADOR/ESPEC. ASUNTOS CORPORATIVOS | J14: DIRECTOR OFERTAS Y PRESUPUESTO | K14: JEFE COMUNICACIÓN INTERNA | L14: AUDITOR NOCTURNO | O14: GERENTE COMPRAS | P14: GERENTE SEGURIDAD INDUSTRIAL | Q14: ASISTENTE PLANCHAS | R14: GERENTE INVESTIGACION MERCADOS | S14: INGENIERO INTERVENTOR | U14: ELECTRICISTA EXPERTO | V14: GERENTE DIAGNOSTICA | W14: JEFE SANEAMIENTO AMBIENTAL | X14: DIRECTOR OFICINA COMUNICACIONES | Y14: GERENTE FIDUCIA INVERSION | Z14: GERENTE INVESTIGACION DLLO. TECNOLOGICO | AE14: I & D | AF14: M | AG14: ="CATALOGO!$"&AF14&"$3:$"&AF14&"$155" -> CATALOGO!$M$3:$M$155 | AJ14: 14 | AK14: Director / Jefe | AL14: Especialista Sr / Ingeniero / Ejecutivo de Cuenta | AM14: =IF(AK14="","",AK14)&IF(OR(AL14="",AK14=""),""," / ")&AL14 -> Director / Jefe / Especialista Sr / Ingeniero / Ejecutivo de Cuenta
B15: JEFE PROYECTOS | C15: SUPERVISOR DESPRESE | D15: GERENTE FRAUDES | F15: GERENTE REGIONAL (ZONA GEOGRAFICA DENTRO | G15: TRAMITADOR INMOBILIARIO | H15: ANALISTA CATEGORÍA | I15: JEFE RELACIONES PÚBLICAS | J15: GERENTE INVESTIGACION ECONOMICA | K15: DIRECTOR ADMINISTRACION SALARIOS | L15: COORDINADOR EVENTOS | O15: GERENTE IMPORTACIONES | P15: GERENTE MANTENIMIENTO | Q15: ASISTENTE ROTATIVA | R15: JEFE /COORDINADOR/ESPEC. INVESTIGACIÓN MERCADO | S15: INGENIERO PERFORACION SENIOR | U15: ELECTROMECÁNICO | V15: GERENTE DIVISIÓN FARMA | W15: JEFE UNIDAD SALUD | X15: DIRECTOR DEPTO BIENESTAR UNIVERSITARIO | Y15: GERENTE BANCA CORPORATIVA | Z15: JEFE TELECOMUNICACIONES | AE15: JURÍDICA | AF15: N | AG15: ="CATALOGO!$"&AF15&"$3:$"&AF15&"$155" -> CATALOGO!$N$3:$N$155 | AJ15: 13 | AK15: Director / Jefe | AL15: Especialista Sr / Ingeniero / Ejecutivo de Cuenta | AM15: =IF(AK15="","",AK15)&IF(OR(AL15="",AK15=""),""," / ")&AL15 -> Director / Jefe / Especialista Sr / Ingeniero / Ejecutivo de Cuenta
B16: GERENTE ADMINISTRATIVO (ZONA GEOGRAFICA) | C16: SUPERVISOR GRANJA | D16: GERENTE OPERACIONES TELECOMUNICACIONES | F16: GERENTE CAPACITACIÓN VENTAS SR. | G16: MAESTRO OBRA II | H16: PROMOTOR CONSUMO | I16: ANALISTA PLANEACION | J16: GERENTE PLANEACION CONTROL FINANCIERO | K16: JEFE BIENESTAR SOCIAL Y SALUD OCUPACIONAL | L16: SENIOR CLERK | O16: GERENTE IMPORTACIONES Y EXPORTACIONES | P16: DIRECTOR GESTION AMBIENTAL | Q16: AUXILIAR ROTATIVA | R16: JEFE INVESTIGACION MERCADOS | S16: INGENIERO YACIMIENTOS | U16: MECÁNICO AJUSTADOR EXPERTO | V16: GERENTE DIVISIÓN HOSPITALARIA | W16: ANESTESIOLOGO | X16: DIRECTOR RESTAURANTE | Y16: GERENTE REGIONAL | Z16: JEFE SOPORTE TECNICO | AE16: LOGÍSTICA Y SUMINISTROS | AF16: O | AG16: ="CATALOGO!$"&AF16&"$3:$"&AF16&"$155" -> CATALOGO!$O$3:$O$155 | AJ16: 12 | AK16: Director / Jefe | AL16: Especialista / Ingeniero / Ejecutivo de Cuenta | AM16: =IF(AK16="","",AK16)&IF(OR(AL16="",AK16=""),""," / ")&AL16 -> Director / Jefe / Especialista / Ingeniero / Ejecutivo de Cuenta
B17: JEFE ./COORDINADOR ADMINISTRATIVO | C17: CABO CAMPO | D17: JEFE DEPARTAMENTO GESTION RED | F17: GERENTE CUENTA | G17: TOPÓGRAFO | H17: VENDEDOR(A) DROGUERÍA | I17: ANALISTA CORPORATIVO | J17: GERENTE IMPUESTOS | K17: JEFE RELACIONES LABORALES/SINDICALES | L17: SOUS CHEFF | O17: JEFE REGULACIÓN Y REGISTRO | P17: GERENTE ASEGURAMIENTO CALIDAD | R17: COORDINADOR EVENTOS | S17: GEOFISICO | U17: MECÁNICO MANTENIMIENTO | V17: GERENTE DIVISIÓN NUTRICIÓN | W17: BACTERIOLOGO | X17: DIRECTOR CARRERA | Y17: GERENTE BANCA PERSONAL | Z17: JEFE SEGURIDAD SISTEMAS | AE17: MANUFACTURA E INDUSTRIA | AF17: P | AG17: ="CATALOGO!$"&AF17&"$3:$"&AF17&"$155" -> CATALOGO!$P$3:$P$155 | AJ17: 11 | AK17: Coordinador | AL17: Especialista / Ingeniero / Ejecutivo de Cuenta | AM17: =IF(AK17="","",AK17)&IF(OR(AL17="",AK17=""),""," / ")&AL17 -> Coordinador / Especialista / Ingeniero / Ejecutivo de Cuenta
B18: JEFE CENTRO DOCUMENTACION | C18: CABO COSECHA | D18: JEFE INSTALACIONES | F18: DIRECTOR / JEFE COMERCIAL | G18: AUXILIAR INGENIERIA | H18: CAJERO SUPERMERCADO | I18: ASISTENTE PRESIDENTE / VICEPRESIDENTE | J18: DIRECTOR FINANCIERO | K18: DIRECTOR PERSONAL | L18: BARMAN | O18: JEFE PLANEACION Y CONTROL INVENTARIOS | P18: GERENTE CONTROL CALIDAD | R18: ANALISTA PUBLICIDAD | S18: GEOFÍSICO | U18: OPERARIO EXPERTO MÁQUINAS PRODUCCIÓN | V18: DIRECTOR CIENTÍFICO (LABORATORIOS) | W18: DIETISTA - NUTRICIONISTA | X18: DIRECTOR CONSULTORIO JURÍDICO | Y18: DIRECTOR TARJETA DE CREDITO | Z18: JEFE /COORDINADOR/ESPEC. INFRAESTRUCTURA | AE18: MEDIOS | AF18: Q | AG18: ="CATALOGO!$"&AF18&"$3:$"&AF18&"$155" -> CATALOGO!$Q$3:$Q$155 | AJ18: 10 | AK18: Coordinador | AL18: Especialista / Ingeniero / Ejecutivo de Cuenta | AM18: =IF(AK18="","",AK18)&IF(OR(AL18="",AK18=""),""," / ")&AL18 -> Coordinador / Especialista / Ingeniero / Ejecutivo de Cuenta
B19: JEFE SERVICIOS GENERALES | C19: MONITOR CORTE CAÑA | D19: JEFE SOFTWARE ESPECIALIZADO | F19: GERENTE COMERCIAL ZONA | G19: AUXILIAR RESIDENTE | H19: MERCADERISTA | I19: ASISTENTE RELACIONES PUBLICAS - COMUNIC. | J19: GERENTE CREDITO | K19: JEFE PERSONAL | L19: CAPITÁN BOTONES | O19: JEFE LOGÍSTICA Y OPERACIONES | P19: DIRECTOR CALIDAD | R19: CREATIVO | S19: GEÓLOGO | U19: OPERARIO III PRODUCCIÓN | V19: DIRECTOR MEDICO | W19: FISIOTERAPEUTA | X19: JEFE ADMISIONES Y REGISTRO | Y19: GERENTE TARJETA CREDITO | Z19: JEFE INFRAESTRUCTURA | AE19: MERCADEO | AF19: R | AG19: ="CATALOGO!$"&AF19&"$3:$"&AF19&"$155" -> CATALOGO!$R$3:$R$155 | AJ19: 9 | AK19: Coordinador | AL19: Analista Sr / Ingeniero / Asesor Comercial | AM19: =IF(AK19="","",AK19)&IF(OR(AL19="",AK19=""),""," / ")&AL19 -> Coordinador / Analista Sr / Ingeniero / Asesor Comercial
B20: COORDINADOR/ESPEC. SEGURIDAD Y PREVENCIÓN PERDIDAS | C20: MONTADOR PRIMERA | D20: CONSULTOR IT | F20: GERENTE DISTRITO O SUCURSAL | G20: MAESTRO OBRA I | H20: SURTIDOR SUPERMERCADO | J20: GERENTE COSTOS | K20: COORDINADOR/ESPEC./JEFERECLUTAMIENTO Y SELECCIÓN | L20: CAPITÁN ROOM SERVICE | O20: JEFE ADMINISTRACIÓN DEL RIESGO TERRESTRE | P20: JEFE SEGURIDAD INDUSTRIAL | R20: DISEÑADOR GRÁFICO | S20: INGENIERO FACILIDADES | U20: OPERARIO MAQUINARIA PESADA | V20: GERENTE ASUNTOS REGULATORIOS | W20: JEFE DEPARTAMENTO ENFERMERÍA | X20: DIRECTOR BIENESTAR UNIVERSITARIO | Y20: DIRECTOR INGENIERIA FINANCIERA | Z20: JEFE PROYECTOS SISTEMAS | AE20: MINERIA, ENERGIA E HIDROCARBUROS | AF20: S | AG20: ="CATALOGO!$"&AF20&"$3:$"&AF20&"$155" -> CATALOGO!$S$3:$S$155 | AJ20: 8 | AK20: Supervisor | AL20: Analista Sr / Técnico / Operario Especializado / Ingeniero / Asesor Comercial | AM20: =IF(AK20="","",AK20)&IF(OR(AL20="",AK20=""),""," / ")&AL20 -> Supervisor / Analista Sr / Técnico / Operario Especializado / Ingeniero / Asesor Comercial
B21: JEFE SEGURIDAD FISICA | C21: OPERADOR CENTRIFUGAS PRIMERA | D21: CONSULTOR PRE-VENTA (PRODUCTO/TÉCNICO) | F21: JEFE TELEMARKETING - ACTIVO | G21: AUXILIAR TECNICO | H21: AUXILIAR CATEGORÍA | J21: CONTRALOR | K21: PSICOLOGO | L21: CAPITÁN SERVICIO | O21: JEFE CENTRO DISTRIBUCIÓN | P21: JEFE SEGURIDAD LABORAL | R21: ANALISTA MERCADEO | S21: INGENIERO PERFORACIONES | U21: SOLDADOR EXPERTO | V21: GERENTE DIVISIÓN AGROQUÍMICA | W21: JEFE FARMACIA | X21: ADMINISTRADOR SALA DE COMPUTO | Y21: GERENTE PREVENCIÓN | Z21: JEFE SAP | AE21: OPERACIONES | AF21: T | AG21: ="CATALOGO!$"&AF21&"$3:$"&AF21&"$155" -> CATALOGO!$T$3:$T$155 | AJ21: 7 | AK21: Supervisor | AL21: Analista / Técnico / Operario Especializado / Ingeniero / Asesor Comercial | AM21: =IF(AK21="","",AK21)&IF(OR(AL21="",AK21=""),""," / ")&AL21 -> Supervisor / Analista / Técnico / Operario Especializado / Ingeniero / Asesor Comercial
B22: SUPERVISOR SEGURIDAD Y VIGILANCIA | C22: OPERADOR CRISTALIZADORES | D22: COORDINADOR IMPLEMENTACIÓN | F22: JEFE SERVICIO AL CLIENTE | G22: AYUDANTE ENTENDIDO | J22: GERENTE CONTABILIDAD | K22: COORDINADOR NOMINA | L22: CORTADOR CARNES - BOUCHER | O22: JEFE DESPACHOS | P22: JEFE PRODUCCION | R22: ANALISTA SR PRODUCTOS | S22: INGENIERO PRODUCCIÓN | U22: INSPECTOR CALIDAD | V22: JEFE PRODUCCIÓN - CREMAS | W22: MEDICO ESPECIALISTA | X22: BIBLIOTECOLOGO | Y22: GERENTE NACIONAL SINIESTROS | Z22: JEFE CENTRO COMPUTO | AE22: OPERARIOS | AF22: U | AG22: ="CATALOGO!$"&AF22&"$3:$"&AF22&"$155" -> CATALOGO!$U$3:$U$155 | AJ22: 6 | AK22: Supervisor | AL22: Analista / Técnico / Operario Especializado / Asesor Comercial | AM22: =IF(AK22="","",AK22)&IF(OR(AL22="",AK22=""),""," / ")&AL22 -> Supervisor / Analista / Técnico / Operario Especializado / Asesor Comercial
B23: JEFE SUCURSAL | C23: OPERADOR MESA CAÑA | D23: COORDINADOR TÉCNICO INTERCONEXIÓN | F23: JEFE RELACIONES PÚBLICAS - COMUNICACIONES | G23: OFICIAL DE CONSTRUCCION II | J23: DIRECTOR CONTABILIDAD | K23: JEFE NOMINA | L23: HOUSE MAN | O23: JEFE LOGISTICA | P23: JEFE PLANEACION Y CONTROL PRODUCCIÓN | R23: ANALISTA MERCADEO / INVESTIGACION DE MERCADOS | S23: INGENIERO RESERVORIO | U23: TORNERO | V23: JEFE PRODUCCIÓN - LÍQUIDOS | W23: MEDICO GENERAL | X23: COORDINADOR ACADEMICO FACULTAD | Y23: GERENTE REASEGURO | Z23: JEFE PROCESAMIENTO DATOS | AE23: QUÍMICO Y FARMA | AF23: V | AG23: ="CATALOGO!$"&AF23&"$3:$"&AF23&"$155" -> CATALOGO!$V$3:$V$155 | AJ23: 5 | AL23: Auxiliar/Operario III / Representante de Ventas Sr | AM23: =IF(AK23="","",AK23)&IF(OR(AL23="",AK23=""),""," / ")&AL23 -> Auxiliar/Operario III / Representante de Ventas Sr
B24: PROFESIONAL SENIOR | C24: OPERADOR MOLINOS | D24: ANALISTA GERENCIA DE PROYECTOS - ESPECIALISTA | F24: JEFE CAPACITACIÓN VENTAS | G24: ALBAÑIL | J24: JEFE TESORERIA | K24: COORDINADOR/ESPEC./JEFEENTRENAMIENTO Y DESARROLLO | L24: JEFE TURNO | O24: JEFE COMPRAS | P24: JEFE PLANEACION PRODUCCION | R24: ASISTENTE PROMOCION PUBLICITARIA | S24: LÍDER CONTRATOS | U24: AUXILIAR VEHICULO | V24: ASESOR MEDICO | W24: NUTRICIONISTA | X24: COORDINADOR AREA | Y24: GERENTE TÉCNICO | Z24: JEFE INVESTIGACION TECNOLOGICA | AE24: SERVICIOS DE SALUD | AF24: W | AG24: ="CATALOGO!$"&AF24&"$3:$"&AF24&"$155" -> CATALOGO!$W$3:$W$155 | AJ24: 4 | AL24: Auxiliar / Operario II / Representante de Ventas Sr | AM24: =IF(AK24="","",AK24)&IF(OR(AL24="",AK24=""),""," / ")&AL24 -> Auxiliar / Operario II / Representante de Ventas Sr
B25: JEFE ARCHIVO | C25: AYUDANTE MOLINOS | D25: CONSULTOR CONTRATOS, LICITACIONES Y PROPUESTAS - JR. | F25: JEFE ADMINISTRACION VENTAS | G25: AYUDANTE OBRA | J25: JEFE SEGUROS | K25: COORDINADOR/ESPEC./JEFECOMPENSACIÓN Y BENEFICIOS | L25: MAITRE | O25: DIRECTOR O JEFE COMERCIO EXTERIOR | P25: JEFE MANTENIMIENTO | R25: ASISTENTE MERCADEO | S25: LÍDER GEOLOGÍA | U25: CONDUCTOR VEHÍCULO LIVIANO | V25: DIRECTOR DIVISIÓN DIAGNOSTICO | W25: ODONTOLOGO ESPECIALISTA | X25: COORDINADOR INVESTIGACION | Y25: GERENTE SUCURSAL | Z25: JEFE SISTEMAS | AE25: SERVICIOS EDUCATIVOS | AF25: X | AG25: ="CATALOGO!$"&AF25&"$3:$"&AF25&"$155" -> CATALOGO!$X$3:$X$155 | AJ25: 3 | AL25: Auxiliar / Operario I / Representante de Ventas Jr | AM25: =IF(AK25="","",AK25)&IF(OR(AL25="",AK25=""),""," / ")&AL25 -> Auxiliar / Operario I / Representante de Ventas Jr
B26: SECRETARIA EJECUTIVA PRESIDENCIA | C26: AYUDANTE TACHOS | D26: ARCHIVO | F26: INGENIERO VENTAS | G26: OFICIAL DE CONSTRUCCION I | J26: JEFE RIESGOS | K26: ABOGADO | L26: TELEFONISTA | O26: JEFE ADUANA | P26: JEFE MANTENIMIENTO ELECTRICO | R26: AUXILIAR AYUDAS AUDIOVISUALES | S26: LIDER PERFORACIÓN | U26: HERRAMENTISTA II | V26: JEFE ACABADO | W26: ODONTOLOGO GENERAL | X26: COORDINADOR POSTGRADO | Y26: GERENTE SUCURSAL PRINCIPAL | Z26: INGENIERO TELECOMUNICACIONES | AE26: SERVICIOS FINANCIEROS Y SEGUROS | AF26: Y | AG26: ="CATALOGO!$"&AF26&"$3:$"&AF26&"$155" -> CATALOGO!$Y$3:$Y$155 | AJ26: 2 | AL26: Auxiliar / Operario I / Representante de Ventas Jr | AM26: =IF(AK26="","",AK26)&IF(OR(AL26="",AK26=""),""," / ")&AL26 -> Auxiliar / Operario I / Representante de Ventas Jr
B27: ANALISTA PROYECTOS | C27: CONDUCTOR REMOLCADOR CAÑA | D27: ASESOR SUSCRIPCIONES | F27: VENDEDOR TÉCNICO/ENGIENERO | J27: JEFE PRESUPUESTO | K27: REPRESENTANTE RELACIONES LABORALES | L27: ASISTENTE ALIMENTOS Y BEBIDAS | O27: JEFE EXPORTACIONES | P27: JEFE CONTROL CALIDAD | R27: AUXILIAR MERCADEO | S27: LIDER RESERVORIOS | U27: OPERARIO ENVOLTURA | V27: JEFE DIVISIÓN SERVICIOS HOSPITALARIOS | W27: ORTOPEDISTA | X27: DECANO TIPO B | Y27: GERENTE MESA CONTROL | Z27: DISEÑADOR GRAFICO WEB | AE27: TECNOLOGÍA E INFORMÁTICA | AF27: Z | AG27: ="CATALOGO!$"&AF27&"$3:$"&AF27&"$155" -> CATALOGO!$Z$3:$Z$155 | AJ27: 1 | AL27: Operario I / Ayudante | AM27: =IF(AK27="","",AK27)&IF(OR(AL27="",AK27=""),""," / ")&AL27 -> Operario I / Ayudante
B28: ANALISTA PROCESOS | C28: MONTADOR SEGUNDA | D28: DIGITADOR CORRECTOR | F28: REPRESENTANTE TELE-VENTAS | J28: JEFE PLANEACION FINANCIERA | K28: ANALISTA RECLUTAMIENTO Y SELECCIÓN | L28: PRIMER COCINERO | O28: JEFE IMPORTACIONES | P28: JEFE LABORATORIO | R28: AUXILIAR MERCADEO Y VENTAS | S28: SUPERVISOR FACILIDADES | U28: OPERARIO PREPARADOR PRODUCTOS QUIMICOS | V28: JEFE PROCESOS | W28: PATÓLOGO | X28: INVESTIGADOR | Y28: GERENTE EXÁMENES MÉDICOS | Z28: WEB MASTER | AE28: TEXTILES CONFECCIONES Y CALZADO | AF28: AA | AG28: ="CATALOGO!$"&AF28&"$3:$"&AF28&"$155" -> CATALOGO!$AA$3:$AA$155
B29: ANALISTA ORGANIZACION Y METODOS | C29: AYUDANTE VACUNACIÓN | F29: SUPERVISOR TELEMARKETING - ACTIVO | J29: JEFE /COORDINADOR/ESPEC. RELACIONES CON INVERSIONISTAS | K29: ASISTENTE SALUD OCUPACIONAL | L29: AUXILIAR BAR | O29: JEFE IMPORTACIONES Y EXPORTACIONES | P29: JEFE LABORATORIO/CONTROL CALIDAD | S29: SUPERVISOR GEOLOGÍA | U29: OPERADOR I | V29: COORDINADOR/SUPV. FARMACOVIGILÂNCIA | W29: PEDÍATRA | X29: JEFE ADQUISIONES BIBLIOTECA | Y29: GERENTE PRESTADORES MÉDICOS | Z29: INGENIERO SOPORTE TECNICO | AE29: VEHÍCULOS Y PARTES | AF29: AB | AG29: ="CATALOGO!$"&AF29&"$3:$"&AF29&"$155" -> CATALOGO!$AB$3:$AB$155
B30: ANALISTA ADMINISTRATIVO | C30: GALPONEROS GRANJA | F30: COORDINADOR ATENCIÓN AL CONSUMIDOR | J30: JEFE INVERSIONES | K30: SUPERVISOR SEGURIDAD INDUSTRIAL/ SALUD OCUPACIONAL | L30: AUXILIAR COCINA | O30: JEFE OPERACIONES INTERNACIONALES | P30: JEFE INGENIERIA | S30: SUPERVISOR OPERACIONES | U30: OPERADOR II | V30: INGENIERO CERTIFICACIÓN | W30: PSIQUIATRA | X30: JEFE PROCESOS TECNICOS BIBLIOTECA | Y30: GTE INGENIEROS INSPECCIÓN | Z30: SUPERVISOR HELP DESK
B31: ASISTENTE ADMINISTRATIVO | F31: INGENIERO SERVICIOS TÉCNICOS (CAMPO) | J31: JEFE IMPUESTOS | K31: ANALISTA RECURSOS HUMANOS (GENERALISTA) | L31: AUXILIAR COCINA I | O31: GERENTE ALMACÉN | P31: JEFE INGENIERIA INDUSTRIAL | S31: SUPERVISOR PRODUCCIÓN | U31: AYUDANTE ALMACÉN | V31: MICROBIÓLOGO | W31: ENFERMERA | X31: JEFE SERVICIOS AL PUBLICO BIBLIOTECA | Y31: GERENTE SEGUROS GENERALES | Z31: ADMINISTRADOR BASE DE DATOS
B32: ESCOLTA PERSONAL | F32: JEFE CALL CENTER | J32: JEFE FINANCIERO | K32: ANALISTA NOMINA | L32: AUXILIAR HABITACIONES | O32: COORDINADOR REGULATORIO | P32: JEFE PLANTA | S32: SUPERVISOR RESERVORIO | U32: AYUDANTE MANTENIMIENTO | V32: QUIMICO- FARMACEUTICO | W32: PSICÓLOGO CLÍNICO | X32: PROFESOR ASISTENTE TIPO A | Y32: GERENTE OPERACIONES | Z32: ADMINISTRADOR REDES
B33: RECEPCIONISTA | F33: JEFEPLANEACION VENTAS | J33: JEFE CREDITO Y COBRANZAS | K33: ANALISTA CAPACITACIÓN Y DESARROLLO | L33: AUXILIAR LAVANDERÍA | O33: COORDINADOR DESARROLLO PROVEEDORES | P33: JEFE /COORDINADOR/ESPEC. MEDIO AMBIENTE | S33: INGENIERO HSEQ | U33: AYUDANTE MECÁNICA | V33: REP. VENTAS - ESPECIALIDADES | W33: TÉCNICO RAYOS X | X33: PROFESOR ASOCIADO TIPO A | Y33: DIRECTOR FONDO COMUN | Z33: INGENIERO REDES
B34: RECEPCIONISTA BILINGUE | F34: ANALISTA CUENTAS CLAVES | J34: JEFE COSTOS | K34: ANALISTA COMUNICACIONES INTERNAS | L34: AUXILIAR MINIBAR | O34: INGENIERO DESARROLLO PROVEEDORES | P34: JEFE AMBIENTAL | S34: TÉCNICO ELECTRICISTA INDUSTRIA | U34: ELECTRICISTA INSTALADOR | V34: REP. VENTAS - HOSPITALES | W34: TÉCNICO TERAPIA OCUPACIONAL | X34: PROFESOR CATEDRA PREGRADO TIPO A | Y34: GERENTE PRODUCTO O NEGOCIO FIDUCIARIO | Z34: COORDINADOR/JEFEOPERACIÓN SISTEMAS
B35: SECRETARIA BILINGÜE | F35: REPRESENTANTE VENTAS SENIOR | J35: JEFE CONTABILIDAD | K35: ANALISTA COMPENSACIÓN Y BENEFICIOS | L35: CONSERJE | O35: COORDINADOR/JEFEPLANEACION LOGÍSTICA | P35: JEFE ./COORDINADOR ESP. ASEGURAMIENTO CALIDAD | S35: TÉCNICO ELECTRÓNICA | U35: EMPACADOR PRODUCTOS | V35: JEFE FÍSICO - QUÍMICO | W35: CAPELLÁN | X35: PROFESOR CATEDRA PREGRADO TIPO B | Y35: GERENTE CREDITO PERSONAS | Z35: INGENIERO SISTEMAS
B36: SECRETARIA EJECUTIVA | F36: SUPERVISOR VENTAS | J36: JEFE CARTERA | K36: ASISTENTE / ANALISTA COMPENSACIÓN | L36: LENCERÍA - COSTURERA | O36: JEFE MATERIALES | P36: JEFE ASEGURAMIENTO CALIDAD | S36: TÉCNICO EXPLORACIÓN | U36: OPERARIO I PRODUCCIÓN | V36: JEFE LÍQUIDOS | W36: PROMOTORA SOCIAL | X36: PROFESOR INSTRUCTOR TIPO A | Y36: GERENTE CREDITO CORPORATIVO | Z36: INGENIERO DESARROLLO APLICACIONES
B37: SECRETARIA GENERAL | F37: OPER. TELEMARKETING - ACTIVO | J37: COORDINADOR/ESPEC./JEFEPRESUPUESTOS | K37: ASISTENTE BIENESTAR SOCIAL | L37: MESERO | O37: COORDINADOR ABASTECIMIENTO Y LOGÍSTICA | P37: INGENIERO SEGURIDAD LABORAL | S37: TÉCNICO MECÁNICO | U37: OPERARIO II PRODUCCIÓN | V37: JEFE MICROBIOLOGÍA | W37: AYUDANTE ENFERMERÍA | X37: PROFESOR TITULAR TIPO A | Y37: GERENTE CONTROL PERDIDAS | Z37: INGENIERO INFORMÁTICA
B38: PROFESIONAL EN ENTRENAMIENTO | F38: ANALISTA SERVICIOS AL CLIENTE | J38: COORDINADOR/ESPEC./JEFEPLANEACION/ANAL. FINANCIERA | K38: ANALISTA ADMINISTRACIÓN RH | L38: MESEROS | O38: SUPERVISOR LOGÍSTICA Y OPERACIONES | P38: INGENIERO PRODUCCION | S38: TECNÓLOGO PRODUCCIÓN | U38: AUXILIAR CALIDAD | V38: JEFE SOLUCIONES | W38: INSTRUMENTADOR | X38: VICEDECANO | Y38: GTE COMERCIAL CANAL RETAIL | Z38: DISEÑADOR WEB
B39: PROFESIONAL JUNIOR | F39: ANALISTA DESARROLLO NEGOCIOS | J39: NEGOCIADOR | K39: ASISTENTE GESTION HUMANA | L39: PASTELERO - PANADERO | O39: COORDINADOR/JEFEDISTRIBUCIÓN | P39: INGENIERO PROCESOS | S39: SUPERVISOR ADMINISTRATIVO | U39: AUXILIAR LABORATORIO | V39: JEFE TABLETERIA | W39: RADIÓLOGO | X39: JEFE PRESUPUESTO (EDUCACION) | Y39: GERENTE CONVENIOS | Z39: EDITOR WEB
B40: SUPERNUMERARIO NO FINANCIERO | F40: ANALISTA CAPACITACIÓN VENTAS | J40: COORDINADOR/ESPEC./JEFEIMPUESTOS | K40: ASISTENTE ADMINISTRACIÓN RH | L40: PORTERO | O40: COMPRADOR TÉCNICO | P40: SUPERVISOR PROCESOS | S40: ASISTENTE AYUDAS A LA COMUNIDAD | U40: AUXILIAR BODEGA | V40: JEFE VALIDACIONES | W40: REGENTE DE FARMACIA | X40: COORDINADOR PROMOCION UNIVERSITARIA | Y40: GERENTE ZONA | Z40: ANALISTA SOPORTE - TI
B41: CONDUCTOR GERENCIA | F41: ANALISTA ATENCIÓN AL CONSUMIDOR | J41: COORDINADOR /ESPEC./JEFEFINANZAS | K41: AUXILIAR GESTION HUMANA | L41: PREPARADOR ALIMENTOS | O41: JEFE ALMACEN | P41: INGENIERO MANTENIMIENTO | S41: CONDUCTOR CAMIÓN PESADO | U41: AUXILIAR DESPACHOS | V41: SUPERVISOR AGROPECUARIO | W41: CONDUCTOR AMBULANCIA | X41: COORDINADOR CULTURAL Y DEPORTIVO | Y41: GERENTE COASEGUROS | Z41: ASISTENTE HELP DESK
...

Sheet Hoja4
C3: CATEGORIA | D3: RUTA CARRERA GERENCIAL | E3: RUTA CARRERA CONTRIBUCION INDIVIDUAL | F3: PISTA
C4: 25 | D4: Presidente Global | F4: =IF(D4="","",D4)&IF(OR(E4="",D4=""),""," / ")&E4 -> Presidente Global
